<?xml version="1.0"?>
<robot xmlns:xacro="http://www.ros.org/wiki/xacro">

  <!--
    Tekerlek modülü.
    - 2 adet diferansiyel sürücü tekerleği (sol/sağ, base_link ekseninde)
    - 2 adet küresel caster (ön/arka, denge için)
  -->

  <xacro:macro name="drive_wheel" params="prefix y_reflect">
    <link name="${prefix}_wheel_link">
      <visual>
        <origin xyz="0 0 0" rpy="${pi/2} 0 0"/>
        <geometry>
          <cylinder radius="${wheel_radius}" length="${wheel_width}"/>
        </geometry>
        <material name="wheel_black"/>
      </visual>

      <collision>
        <origin xyz="0 0 0" rpy="${pi/2} 0 0"/>
        <geometry>
          <cylinder radius="${wheel_radius}" length="${wheel_width}"/>
        </geometry>
      </collision>

      <xacro:inertial_cylinder mass="${wheel_mass}"
                               radius="${wheel_radius}" length="${wheel_width}">
        <origin xyz="0 0 0" rpy="${pi/2} 0 0"/>
      </xacro:inertial_cylinder>
    </link>

    <joint name="${prefix}_wheel_joint" type="continuous">
      <parent link="base_link"/>
      <child  link="${prefix}_wheel_link"/>
      <origin xyz="${wheel_x_offset} ${y_reflect * wheel_separation/2} 0" rpy="0 0 0"/>
      <axis xyz="0 1 0"/>
      <dynamics damping="0.05" friction="0.05"/>
    </joint>

    <!-- Gazebo sürtünme parametreleri -->
    <gazebo reference="${prefix}_wheel_link">
      <mu1>1.0</mu1>
      <mu2>1.0</mu2>
      <kp>1000000.0</kp>
      <kd>100.0</kd>
    </gazebo>
  </xacro:macro>

  <xacro:drive_wheel prefix="left"  y_reflect="1"/>
  <xacro:drive_wheel prefix="right" y_reflect="-1"/>


  <xacro:macro name="caster_wheel" params="prefix x_reflect">
    <link name="${prefix}_caster_link">
      <visual>
        <origin xyz="0 0 0" rpy="0 0 0"/>
        <geometry>
          <sphere radius="${caster_radius}"/>
        </geometry>
        <material name="caster_grey"/>
      </visual>

      <collision>
        <origin xyz="0 0 0" rpy="0 0 0"/>
        <geometry>
          <sphere radius="${caster_radius}"/>
        </geometry>
      </collision>

      <xacro:inertial_sphere mass="${caster_mass}" radius="${caster_radius}">
        <origin xyz="0 0 0" rpy="0 0 0"/>
      </xacro:inertial_sphere>
    </link>

    <joint name="${prefix}_caster_joint" type="fixed">
      <parent link="base_link"/>
      <child  link="${prefix}_caster_link"/>
      <origin xyz="${x_reflect * caster_x_offset} 0 ${-(wheel_radius - caster_radius)}"
              rpy="0 0 0"/>
    </joint>

    <!-- Caster küreleri serbest dönsün diye düşük sürtünme -->
    <gazebo reference="${prefix}_caster_link">
      <mu1>0.05</mu1>
      <mu2>0.05</mu2>
    </gazebo>
  </xacro:macro>

  <xacro:caster_wheel prefix="front" x_reflect="1"/>
  <xacro:caster_wheel prefix="rear"  x_reflect="-1"/>

</robot>
